<?xml version="1.0"?>
<robot name="robotito" xmlns:xacro="http://www.ros.org/wiki/xacro">

  <!-- Include inertial macros -->
  <xacro:include filename="inertial_macros.xacro" />

  <!-- Robot Properties -->
  <xacro:property name="chassis_length" value="0.4" />
  <xacro:property name="chassis_width" value="0.3" />
  <xacro:property name="chassis_height" value="0.1" />
  <xacro:property name="chassis_mass" value="1.0" />

  <xacro:property name="wheel_radius" value="0.1" />
  <xacro:property name="wheel_thickness" value="0.04" />
  <xacro:property name="wheel_mass" value="0.1" />
  <xacro:property name="wheel_offset_x" value="0.1" />
  <xacro:property name="wheel_offset_y" value="0.1705" />
  <xacro:property name="wheel_offset_z" value="0.0" />


  <xacro:property name="caster_wheel_radius" value="0.025" />
  <xacro:property name="caster_wheel_mass" value="0.05" />
  <xacro:property name="caster_wheel_offset_x" value="0.15" />
  <xacro:property name="caster_wheel_offset_z" value="-0.075" />

  <!-- Materials -->
  <material name="white">
    <color rgba="1 1 1 1" />
  </material>

  <material name="orange">
    <color rgba="1 0.3 0.1 1"/>
  </material>

  <material name="blue">
    <color rgba="0.2 0.2 1 1"/>
  </material>

  <material name="black">
    <color rgba="0 0 0 1"/>
  </material>

  <material name="green">
    <color rgba="0 1 0 1"/>
  </material>


  <!-- BASE LINK -->
  <link name="base_link">
    <visual>
        <origin xyz="0 0 0" rpy="0 0 0"/>
        <geometry>
            <box size="${chassis_length} ${chassis_width} ${chassis_height}"/>
        </geometry>
        <material name="green"/>
    </visual>
    <collision>
        <origin xyz="0 0 0" rpy="0 0 0"/>
        <geometry>
            <box size="${chassis_length} ${chassis_width} ${chassis_height}"/>
        </geometry>
    </collision>
    <xacro:inertial_box mass="0.5" x="${chassis_length}" y="${chassis_width}" z="${chassis_height}">
        <origin xyz="0 0 0" rpy="0 0 0"/>
    </xacro:inertial_box>
  </link>


  <!-- WHEELS -->

  <!-- Wheel Macro -->
  <xacro:macro name="wheel" params="prefix offset_y">
    <link name="${prefix}_wheel">
      <visual>
        <origin xyz="0 0 0" rpy="1.5707 0 0 "/>
        <geometry>
            <cylinder radius="${wheel_radius}" length="${wheel_thickness}"/>
        </geometry>
        <material name="black"/>
      </visual>
      <collision>
        <origin xyz="0 0 0" rpy="1.5707 0 0 "/>
        <geometry>
            <cylinder radius="${wheel_radius}" length="${wheel_thickness}"/>
        </geometry>
      </collision>
      <xacro:inertial_cylinder mass="${wheel_mass}" length="${wheel_thickness}" radius="${wheel_radius}">
        <origin xyz="0 0 0" rpy="1.5707 0 0"/>
      </xacro:inertial_cylinder>
    </link>

    <joint name="${prefix}_wheel_joint" type="continuous">
      <parent link="base_link"/>
      <child link="${prefix}_wheel"/>
      <origin xyz="${-wheel_offset_x} ${offset_y} ${wheel_offset_z}" rpy="0 0 0"/>
      <axis xyz="0 1 0"/>
    </joint>
  </xacro:macro>

  <xacro:wheel prefix="left" offset_y="${wheel_offset_y}"/>
  <xacro:wheel prefix="right" offset_y="${-wheel_offset_y}"/>


  <!-- CASTER WHEEL -->

  <link name="caster_wheel">
    <visual>
      <geometry>
        <sphere radius="${caster_wheel_radius}"/>
      </geometry>
      <material name="white"/>
    </visual>
    <collision>
      <geometry>
        <sphere radius="${caster_wheel_radius}"/>
      </geometry>
    </collision>
    <xacro:inertial_sphere mass="${caster_wheel_mass}" radius="${caster_wheel_radius}">
        <origin xyz="0 0 0" rpy="0 0 0"/>
    </xacro:inertial_sphere>
  </link>

  <joint name="caster_joint" type="fixed">
    <parent link="base_link"/>
    <child link="caster_wheel"/>
    <origin xyz="${caster_wheel_offset_x} 0 ${caster_wheel_offset_z}"/>
  </joint>

</robot>